<?xml version="1.0" encoding="utf-8"?>
<robot xmlns:xacro="http://wiki.ros.org/xacro">

  <xacro:macro name="tm5_900_robot" params="parent *origin prefix physical_parameters_file kinematics_parameters_file joint_limits_parameters_file">

    <xacro:property name="phys_params" value="${xacro.load_yaml(physical_parameters_file)}"/>
    <xacro:property name="inertia" value="${phys_params['inertia_parameters']}"/>

    <xacro:property name="kin_params" value="${xacro.load_yaml(kinematics_parameters_file)}"/>
    <xacro:property name="kinematics" value="${kin_params['kinematics']}"/>

    <xacro:property name="limit_params" value="${xacro.load_yaml(joint_limits_parameters_file)}"/>
    <xacro:property name="limits" value="${limit_params['joint_limits']}"/>


    <joint name="${prefix}base_joint" type="fixed">
      <xacro:insert_block name="origin" />
      <parent link="${parent}" />
      <child link="${prefix}base_link" />
    </joint>

    <link name="${prefix}base_link">
      <inertial>
        <origin xyz="${inertia['center_of_mass']['base_cog']['x']} ${inertia['center_of_mass']['base_cog']['y']} ${inertia['center_of_mass']['base_cog']['z']}" rpy="0 0 0" />
        <mass value="${inertia['base_mass']}" />
        <inertia ixx="${inertia['tensor']['base']['ixx']}" ixy="${inertia['tensor']['base']['ixy']}" ixz="${inertia['tensor']['base']['ixz']}" iyy="${inertia['tensor']['base']['iyy']}" iyz="${inertia['tensor']['base']['iyz']}" izz="${inertia['tensor']['base']['izz']}" />
      </inertial>
      <visual>
        <origin xyz="0 0 0" rpy="0 0 0" />
        <geometry>
          <mesh filename="package://tm5_900/meshes/base_link.STL" />
        </geometry>
        <material name="">
          <color rgba="0.792156862745098 0.819607843137255 0.933333333333333 1" />
        </material>
      </visual>
      <collision>
        <origin xyz="0 0 0" rpy="0 0 0" />
        <geometry>
          <mesh filename="package://tm5_900/meshes/base_link.STL" />
        </geometry>
      </collision>
    </link>

    <link name="${prefix}link1">
      <inertial>
        <origin xyz="${inertia['center_of_mass']['link1_cog']['x']} ${inertia['center_of_mass']['link1_cog']['y']} ${inertia['center_of_mass']['link1_cog']['z']}" rpy="0 0 0" />
        <mass value="${inertia['link1_mass']}" />
        <inertia ixx="${inertia['tensor']['link1']['ixx']}" ixy="${inertia['tensor']['link1']['ixy']}" ixz="${inertia['tensor']['link1']['ixz']}" iyy="${inertia['tensor']['link1']['iyy']}" iyz="${inertia['tensor']['link1']['iyz']}" izz="${inertia['tensor']['link1']['izz']}" />
      </inertial>
      <visual>
        <origin xyz="0 0 0" rpy="0 0 0" />
        <geometry>
          <mesh filename="package://tm5_900/meshes/link1.STL" />
        </geometry>
        <material name="">
          <color rgba="0.792156862745098 0.819607843137255 0.933333333333333 1" />
        </material>
      </visual>
      <collision>
        <origin xyz="0 0 0" rpy="0 0 0" />
        <geometry>
          <mesh filename="package://tm5_900/meshes/link1.STL" />
        </geometry>
      </collision>
    </link>

    <joint name="${prefix}link1_joint" type="revolute">
      <origin xyz="${kinematics['link1']['x']} ${kinematics['link1']['y']} ${kinematics['link1']['z']}" 
              rpy="${kinematics['link1']['roll']} ${kinematics['link1']['pitch']} ${kinematics['link1']['yaw']}" />
      <parent link="${prefix}base_link" />
      <child link="${prefix}link1" />
      <axis xyz="0 0 -1" />
      <limit lower="${limits['link1_joint']['min_position']}" 
             upper="${limits['link1_joint']['max_position']}" 
             effort="${limits['link1_joint']['max_effort']}" 
             velocity="${limits['link1_joint']['max_velocity']}" />
      <dynamics damping="0.1" friction="0.1" />
    </joint>

    <link name="${prefix}link2">
      <inertial>
        <origin xyz="${inertia['center_of_mass']['link2_cog']['x']} ${inertia['center_of_mass']['link2_cog']['y']} ${inertia['center_of_mass']['link2_cog']['z']}" rpy="0 0 0" />
        <mass value="${inertia['link2_mass']}" />
        <inertia ixx="${inertia['tensor']['link2']['ixx']}" ixy="${inertia['tensor']['link2']['ixy']}" ixz="${inertia['tensor']['link2']['ixz']}" iyy="${inertia['tensor']['link2']['iyy']}" iyz="${inertia['tensor']['link2']['iyz']}" izz="${inertia['tensor']['link2']['izz']}" />
      </inertial>
      <visual>
        <origin xyz="0 0 0" rpy="0 0 0" />
        <geometry>
          <mesh filename="package://tm5_900/meshes/link2.STL" />
        </geometry>
        <material name="">
          <color rgba="0.792156862745098 0.819607843137255 0.933333333333333 1" />
        </material>
      </visual>
      <collision>
        <origin xyz="0 0 0" rpy="0 0 0" />
        <geometry>
          <mesh filename="package://tm5_900/meshes/link2.STL" />
        </geometry>
      </collision>
    </link>

    <joint name="${prefix}link2_joint" type="revolute">
      <origin xyz="${kinematics['link2']['x']} ${kinematics['link2']['y']} ${kinematics['link2']['z']}" 
              rpy="${kinematics['link2']['roll']} ${kinematics['link2']['pitch']} ${kinematics['link2']['yaw']}" />
      <parent link="${prefix}link1" />
      <child link="${prefix}link2" />
      <axis xyz="0 0 -1" />
      <limit lower="${limits['link2_joint']['min_position']}" 
             upper="${limits['link2_joint']['max_position']}" 
             effort="${limits['link2_joint']['max_effort']}" 
             velocity="${limits['link2_joint']['max_velocity']}" />
      <dynamics damping="0.1" friction="0.1" />
    </joint>

    <link name="${prefix}link3">
      <inertial>
        <origin xyz="${inertia['center_of_mass']['link3_cog']['x']} ${inertia['center_of_mass']['link3_cog']['y']} ${inertia['center_of_mass']['link3_cog']['z']}" rpy="0 0 0" />
        <mass value="${inertia['link3_mass']}" />
        <inertia ixx="${inertia['tensor']['link3']['ixx']}" ixy="${inertia['tensor']['link3']['ixy']}" ixz="${inertia['tensor']['link3']['ixz']}" iyy="${inertia['tensor']['link3']['iyy']}" iyz="${inertia['tensor']['link3']['iyz']}" izz="${inertia['tensor']['link3']['izz']}" />
      </inertial>
      <visual>
        <origin xyz="0 0 0" rpy="0 0 0" />
        <geometry>
          <mesh filename="package://tm5_900/meshes/link3.STL" />
        </geometry>
        <material name="">
          <color rgba="0.792156862745098 0.819607843137255 0.933333333333333 1" />
        </material>
      </visual>
      <collision>
        <origin xyz="0 0 0" rpy="0 0 0" />
        <geometry>
          <mesh filename="package://tm5_900/meshes/link3.STL" />
        </geometry>
      </collision>
    </link>

    <joint name="${prefix}link3_joint" type="revolute">
      <origin xyz="${kinematics['link3']['x']} ${kinematics['link3']['y']} ${kinematics['link3']['z']}" 
              rpy="${kinematics['link3']['roll']} ${kinematics['link3']['pitch']} ${kinematics['link3']['yaw']}" />
      <parent link="${prefix}link2" />
      <child link="${prefix}link3" />
      <axis xyz="0 0 -1" />
      <limit lower="${limits['link3_joint']['min_position']}" 
             upper="${limits['link3_joint']['max_position']}" 
             effort="${limits['link3_joint']['max_effort']}" 
             velocity="${limits['link3_joint']['max_velocity']}" />
      <dynamics damping="0.1" friction="0.1" />
    </joint>

    <link name="${prefix}link4">
      <inertial>
        <origin xyz="${inertia['center_of_mass']['link4_cog']['x']} ${inertia['center_of_mass']['link4_cog']['y']} ${inertia['center_of_mass']['link4_cog']['z']}" rpy="0 0 0" />
        <mass value="${inertia['link4_mass']}" />
        <inertia ixx="${inertia['tensor']['link4']['ixx']}" ixy="${inertia['tensor']['link4']['ixy']}" ixz="${inertia['tensor']['link4']['ixz']}" iyy="${inertia['tensor']['link4']['iyy']}" iyz="${inertia['tensor']['link4']['iyz']}" izz="${inertia['tensor']['link4']['izz']}" />
      </inertial>
      <visual>
        <origin xyz="0 0 0" rpy="0 0 0" />
        <geometry>
          <mesh filename="package://tm5_900/meshes/link4.STL" />
        </geometry>
        <material name="">
          <color rgba="0.792156862745098 0.819607843137255 0.933333333333333 1" />
        </material>
      </visual>
      <collision>
        <origin xyz="0 0 0" rpy="0 0 0" />
        <geometry>
          <mesh filename="package://tm5_900/meshes/link4.STL" />
        </geometry>
      </collision>
    </link>

    <joint name="${prefix}link4_joint" type="revolute">
      <origin xyz="${kinematics['link4']['x']} ${kinematics['link4']['y']} ${kinematics['link4']['z']}" 
              rpy="${kinematics['link4']['roll']} ${kinematics['link4']['pitch']} ${kinematics['link4']['yaw']}" />
      <parent link="${prefix}link3" />
      <child link="${prefix}link4" />
      <axis xyz="0 0 -1" />
      <limit lower="${limits['link4_joint']['min_position']}" 
             upper="${limits['link4_joint']['max_position']}" 
             effort="${limits['link4_joint']['max_effort']}" 
             velocity="${limits['link4_joint']['max_velocity']}" />
      <dynamics damping="0.1" friction="0.1" />
    </joint>

    <link name="${prefix}link5">
      <inertial>
        <origin xyz="${inertia['center_of_mass']['link5_cog']['x']} ${inertia['center_of_mass']['link5_cog']['y']} ${inertia['center_of_mass']['link5_cog']['z']}" rpy="0 0 0" />
        <mass value="${inertia['link5_mass']}" />
        <inertia ixx="${inertia['tensor']['link5']['ixx']}" ixy="${inertia['tensor']['link5']['ixy']}" ixz="${inertia['tensor']['link5']['ixz']}" iyy="${inertia['tensor']['link5']['iyy']}" iyz="${inertia['tensor']['link5']['iyz']}" izz="${inertia['tensor']['link5']['izz']}" />
      </inertial>
      <visual>
        <origin xyz="0 0 0" rpy="0 0 0" />
        <geometry>
          <mesh filename="package://tm5_900/meshes/link5.STL" />
        </geometry>
        <material name="">
          <color rgba="0.792156862745098 0.819607843137255 0.933333333333333 1" />
        </material>
      </visual>
      <collision>
        <origin xyz="0 0 0" rpy="0 0 0" />
        <geometry>
          <mesh filename="package://tm5_900/meshes/link5.STL" />
        </geometry>
      </collision>
    </link>

    <joint name="${prefix}link5_joint" type="revolute">
      <origin xyz="${kinematics['link5']['x']} ${kinematics['link5']['y']} ${kinematics['link5']['z']}" 
              rpy="${kinematics['link5']['roll']} ${kinematics['link5']['pitch']} ${kinematics['link5']['yaw']}" />
      <parent link="${prefix}link4" />
      <child link="${prefix}link5" />
      <axis xyz="0 0 -1" />
      <limit lower="${limits['link5_joint']['min_position']}" 
             upper="${limits['link5_joint']['max_position']}" 
             effort="${limits['link5_joint']['max_effort']}" 
             velocity="${limits['link5_joint']['max_velocity']}" />
      <dynamics damping="0.1" friction="0.1" />
    </joint>

    <link name="${prefix}link6">
      <inertial>
        <origin xyz="${inertia['center_of_mass']['link6_cog']['x']} ${inertia['center_of_mass']['link6_cog']['y']} ${inertia['center_of_mass']['link6_cog']['z']}" rpy="0 0 0" />
        <mass value="${inertia['link6_mass']}" />
        <inertia ixx="${inertia['tensor']['link6']['ixx']}" ixy="${inertia['tensor']['link6']['ixy']}" ixz="${inertia['tensor']['link6']['ixz']}" iyy="${inertia['tensor']['link6']['iyy']}" iyz="${inertia['tensor']['link6']['iyz']}" izz="${inertia['tensor']['link6']['izz']}" />
      </inertial>
      <visual>
        <origin xyz="0 0 0" rpy="0 0 0" />
        <geometry>
          <mesh filename="package://tm5_900/meshes/link6.STL" />
        </geometry>
        <material name="">
          <color rgba="0.792156862745098 0.819607843137255 0.933333333333333 1" />
        </material>
      </visual>
      <collision>
        <origin xyz="0 0 0" rpy="0 0 0" />
        <geometry>
          <mesh filename="package://tm5_900/meshes/link6.STL" />
        </geometry>
      </collision>
    </link>

    <joint name="${prefix}link6_joint" type="revolute">
      <origin xyz="${kinematics['link6']['x']} ${kinematics['link6']['y']} ${kinematics['link6']['z']}" 
              rpy="${kinematics['link6']['roll']} ${kinematics['link6']['pitch']} ${kinematics['link6']['yaw']}" />
      <parent link="${prefix}link5" />
      <child link="${prefix}link6" />
      <axis xyz="0 0 -1" />
      <limit lower="${limits['link6_joint']['min_position']}" 
             upper="${limits['link6_joint']['max_position']}" 
             effort="${limits['link6_joint']['max_effort']}" 
             velocity="${limits['link6_joint']['max_velocity']}" />
      <dynamics damping="0.1" friction="0.1" />
    </joint>

  </xacro:macro>
</robot>