<?xml version="1.0" ?>
<!-- =================================================================================== -->
<!-- |    This document was autogenerated by xacro from src/tm5_900/urdf/tm5_900.urdf.xacro | -->
<!-- |    EDITING THIS FILE BY HAND IS NOT RECOMMENDED                                 | -->
<!-- =================================================================================== -->
<robot name="tm5_900">
  <webots>
    <plugin type="webots_ros2_control::Ros2Control">
      <parameters>$(find tm5_900)/config/ros2_controllersWithGripper.yaml</parameters>
    </plugin>
  </webots>
  <!-- <gazebo>
    <plugin filename="libgazebo_ros2_control.so" name="gazebo_ros2_control">
      <parameters>$(find tm5_900)/config/ros2_controllers.yaml</parameters>
    </plugin>
  </gazebo> -->
  <link name="world"/>
  <link name="gripper_center_tcp"/>
  <joint name="righthand_to_tcp" type="fixed">
    <parent link="gripper_base_link"/>
    <child link="gripper_center_tcp"/>
    <origin rpy="0 0 0" xyz="0 0 0.135"/>
  </joint>
  <joint name="base_joint" type="fixed">
    <origin rpy="0 0 0" xyz="0 0 0"/>
    <parent link="world"/>
    <child link="base_link"/>
  </joint>
  <link name="base_link">
    <inertial>
      <origin rpy="0 0 0" xyz="1.484e-06 0.000238812 0.028483455"/>
      <mass value="1.06337100987987"/>
      <inertia ixx="0.001820182" ixy="1.629e-06" ixz="-5.3e-08" iyy="0.001851119" iyz="-5.617e-06" izz="0.002906595"/>
    </inertial>
    <visual>
      <origin rpy="0 0 0" xyz="0 0 0"/>
      <geometry>
        <mesh filename="package://tm5_900/meshes/base_link.STL"/>
      </geometry>
      <material name="">
        <color rgba="0.792156862745098 0.819607843137255 0.933333333333333 1"/>
      </material>
    </visual>
    <collision>
      <origin rpy="0 0 0" xyz="0 0 0"/>
      <geometry>
        <mesh filename="package://tm5_900/meshes/base_link.STL"/>
      </geometry>
    </collision>
  </link>
  <link name="link1">
    <inertial>
      <origin rpy="0 0 0" xyz="-0.004985528 -0.001349578 0.079820705"/>
      <mass value="1.94965621478227"/>
      <inertia ixx="0.003360488" ixy="-1.7048e-05" ixz="0.000473241" iyy="0.003418932" iyz="0.000128103" izz="0.003748004"/>
    </inertial>
    <visual>
      <origin rpy="0 0 0" xyz="0 0 0"/>
      <geometry>
        <mesh filename="package://tm5_900/meshes/link1.STL"/>
      </geometry>
      <material name="">
        <color rgba="0.792156862745098 0.819607843137255 0.933333333333333 1"/>
      </material>
    </visual>
    <collision>
      <origin rpy="0 0 0" xyz="0 0 0"/>
      <geometry>
        <mesh filename="package://tm5_900/meshes/link1.STL"/>
      </geometry>
    </collision>
  </link>
  <joint name="link1_joint" type="revolute">
    <origin rpy="0.0 0.0 0.0" xyz="0.0 0.0 0.066"/>
    <parent link="base_link"/>
    <child link="link1"/>
    <axis xyz="0 0 -1"/>
    <limit effort="150.0" lower="-4.712" upper="4.712" velocity="3.141"/>
    <dynamics damping="0.1" friction="0.1"/>
  </joint>
  <link name="link2">
    <inertial>
      <origin rpy="0 0 0" xyz="-0.021473094 0.21342247 0.080476736"/>
      <mass value="6.39944621023157"/>
      <inertia ixx="0.029935285" ixy="0.001993175" ixz="-6e-09" iyy="0.010325352" iyz="6e-09" izz="0.030784769"/>
    </inertial>
    <visual>
      <origin rpy="0 0 0" xyz="0 0 0"/>
      <geometry>
        <mesh filename="package://tm5_900/meshes/link2.STL"/>
      </geometry>
      <material name="">
        <color rgba="0.792156862745098 0.819607843137255 0.933333333333333 1"/>
      </material>
    </visual>
    <collision>
      <origin rpy="0 0 0" xyz="0 0 0"/>
      <geometry>
        <mesh filename="package://tm5_900/meshes/link2.STL"/>
      </geometry>
    </collision>
  </link>
  <joint name="link2_joint" type="revolute">
    <origin rpy="1.5708 0.0 -1.3064" xyz="-0.064479 -0.017456 0.0815"/>
    <parent link="link1"/>
    <child link="link2"/>
    <axis xyz="0 0 -1"/>
    <limit effort="150.0" lower="-3.141" upper="3.141" velocity="3.141"/>
    <dynamics damping="0.1" friction="0.1"/>
  </joint>
  <link name="link3">
    <inertial>
      <origin rpy="0 0 0" xyz="0.131851812 0.166464143 0.047068671"/>
      <mass value="2.93877134811613"/>
      <inertia ixx="0.009780698" ixy="-0.005580689" ixz="-3.1608e-05" iyy="0.007155136" iyz="-4.0067e-05" izz="0.014350517"/>
    </inertial>
    <visual>
      <origin rpy="0 0 0" xyz="0 0 0"/>
      <geometry>
        <mesh filename="package://tm5_900/meshes/link3.STL"/>
      </geometry>
      <material name="">
        <color rgba="0.792156862745098 0.819607843137255 0.933333333333333 1"/>
      </material>
    </visual>
    <collision>
      <origin rpy="0 0 0" xyz="0 0 0"/>
      <geometry>
        <mesh filename="package://tm5_900/meshes/link3.STL"/>
      </geometry>
    </collision>
  </link>
  <joint name="link3_joint" type="revolute">
    <origin rpy="3.1416 0.0 -3.0413" xyz="-0.042946 0.42684 0.0"/>
    <parent link="link2"/>
    <child link="link3"/>
    <axis xyz="0 0 -1"/>
    <limit effort="150.0" lower="-2.705" upper="2.705" velocity="3.141"/>
    <dynamics damping="0.1" friction="0.1"/>
  </joint>
  <link name="link4">
    <inertial>
      <origin rpy="0 0 0" xyz="0.000958659 0.004002076 0.058436135"/>
      <mass value="0.784300640139411"/>
      <inertia ixx="0.000777536" ixy="-2.838e-06" ixz="-2.6221e-05" iyy="0.000765864" iyz="-0.000109647" izz="0.000826338"/>
    </inertial>
    <visual>
      <origin rpy="0 0 0" xyz="0 0 0"/>
      <geometry>
        <mesh filename="package://tm5_900/meshes/link4.STL"/>
      </geometry>
      <material name="">
        <color rgba="0.792156862745098 0.819607843137255 0.933333333333333 1"/>
      </material>
    </visual>
    <collision>
      <origin rpy="0 0 0" xyz="0 0 0"/>
      <geometry>
        <mesh filename="package://tm5_900/meshes/link4.STL"/>
      </geometry>
    </collision>
  </link>
  <joint name="link4_joint" type="revolute">
    <origin rpy="-3.1416 0.0 2.4717" xyz="0.2555 0.32257 -0.008"/>
    <parent link="link3"/>
    <child link="link4"/>
    <axis xyz="0 0 -1"/>
    <limit effort="150.0" lower="-3.141" upper="3.141" velocity="3.927"/>
    <dynamics damping="0.1" friction="0.1"/>
  </joint>
  <link name="link5">
    <inertial>
      <origin rpy="0 0 0" xyz="6.3768e-05 -5.283e-06 0.045584635"/>
      <mass value="0.784295948614627"/>
      <inertia ixx="0.000825367" ixy="-6.788e-06" ixz="-0.000111586" iyy="0.000779162" iyz="1.6084e-05" izz="0.000765206"/>
    </inertial>
    <visual>
      <origin rpy="0 0 0" xyz="0 0 0"/>
      <geometry>
        <mesh filename="package://tm5_900/meshes/link5.STL"/>
      </geometry>
      <material name="">
        <color rgba="0.792156862745098 0.819607843137255 0.933333333333333 1"/>
      </material>
    </visual>
    <collision>
      <origin rpy="0 0 0" xyz="0 0 0"/>
      <geometry>
        <mesh filename="package://tm5_900/meshes/link5.STL"/>
      </geometry>
    </collision>
  </link>
  <joint name="link5_joint" type="revolute">
    <origin rpy="-0.53433 -1.5708 -1.2417" xyz="0.011533 0.048343 0.0585"/>
    <parent link="link4"/>
    <child link="link5"/>
    <axis xyz="0 0 -1"/>
    <limit effort="150.0" lower="-3.141" upper="3.141" velocity="3.927"/>
    <dynamics damping="0.1" friction="0.1"/>
  </joint>
  <link name="link6">
    <inertial>
      <origin rpy="0 0 0" xyz="-0.003225184 0.041925552 0.04049585"/>
      <mass value="0.667417377007754"/>
      <inertia ixx="0.000832763" ixy="3.6663e-05" ixz="1.826e-06" iyy="0.000383001" iyz="-1.4287e-05" izz="0.000952325"/>
    </inertial>
    <visual>
      <origin rpy="0 0 0" xyz="0 0 0"/>
      <geometry>
        <mesh filename="package://tm5_900/meshes/link6.STL"/>
      </geometry>
      <material name="">
        <color rgba="0.792156862745098 0.819607843137255 0.933333333333333 1"/>
      </material>
    </visual>
    <collision>
      <origin rpy="0 0 0" xyz="0 0 0"/>
      <geometry>
        <mesh filename="package://tm5_900/meshes/link6.STL"/>
      </geometry>
    </collision>
  </link>
  <joint name="link6_joint" type="revolute">
    <origin rpy="1.5708 0.0 1.4267" xyz="0.057893 -0.0084026 0.0497"/>
    <parent link="link5"/>
    <child link="link6"/>
    <axis xyz="0 0 -1"/>
    <limit effort="150.0" lower="-4.712" upper="4.712" velocity="3.927"/>
    <dynamics damping="0.1" friction="0.1"/>
  </joint>
  <joint name="gripper_mount_joint" type="fixed">
    <origin rpy="0 0 0" xyz="0.0 0.0 0.02"/>
    <parent link="link6"/>
    <child link="gripper_base_link"/>
    <dynamics damping="0" friction="0"/>

  </joint>
  <link name="gripper_base_link">
    <inertial>
      <origin rpy="0 0 0" xyz="0.000718498778430887 -1.74875373432082E-07 0.0459725648476832"/>
      <mass value="0.307675135770669"/>
      <inertia ixx="0.000259141668867471" ixy="-2.09979995789405E-10" ixz="3.31302393015316E-08" iyy="0.000261006032886084" iyz="-1.60469854174508E-09" izz="0.000169214797750628"/>
    </inertial>
    <visual>
      <origin rpy="0 0 0" xyz="0 0 0"/>
      <geometry>
        <mesh filename="package://tm5_900/meshes/gripper_base_link.STL"/>
      </geometry>
      <material name="">
        <color rgba="0.792156862745098 0.819607843137255 0.933333333333333 1"/>
      </material>
    </visual>
    <collision>
      <origin rpy="0 0 0" xyz="0 0 0"/>
      <geometry>
        <mesh filename="package://tm5_900/meshes/gripper_base_link.STL"/>
      </geometry>
    </collision>
  </link>
  <link name="righthand_link">
    <inertial>
      <origin rpy="0 0 0" xyz="-0.00681882336061863 0.0223827823514538 -0.00857761947163638"/>
      <mass value="0.01364966763846"/>
      <inertia ixx="5.80907207521746E-06" ixy="1.32416192549937E-06" ixz="-7.03179293152161E-07" iyy="2.71231748624374E-06" iyz="1.35062598473268E-06" izz="4.9807724616964E-06"/>
    </inertial>
    <visual>
      <origin rpy="0 0 0" xyz="0 0 0"/>
      <geometry>
        <mesh filename="package://tm5_900/meshes/righthand_link.STL"/>
      </geometry>
      <material name="">
        <color rgba="0.792156862745098 0.819607843137255 0.933333333333333 1"/>
      </material>
    </visual>
    <collision>
      <origin rpy="0 0 0" xyz="0 0 0"/>
      <geometry>
        <mesh filename="package://tm5_900/meshes/righthand_link.STL"/>
      </geometry>
    </collision>
  </link>
  <joint name="righthand_joint" type="prismatic">
    <origin rpy="1.5708 0 -1.5708" xyz="0.017642 -0.01429 0.0839"/>
    <parent link="gripper_base_link"/>
    <child link="righthand_link"/>
    <axis xyz="0 0 1"/>
    <limit effort="130" lower="-0.015" upper="0.025" velocity="0.15"/>
    <dynamics damping="0.1" friction="0.1"/>
  </joint>
  <link name="lefthand_link">
    <inertial>
      <origin rpy="0 0 0" xyz="-0.00681882354154159 0.0223827823996961 -0.00857761934860912"/>
      <mass value="0.0136496676273574"/>
      <inertia ixx="5.80907213502822E-06" ixy="1.32416190478303E-06" ixz="-7.03179272696445E-07" iyy="2.71231751798348E-06" iyz="1.35062599298803E-06" izz="4.98077252893434E-06"/>
    </inertial>
    <visual>
      <origin rpy="0 0 0" xyz="0 0 0"/>
      <geometry>
        <mesh filename="package://tm5_900/meshes/lefthand_link.STL"/>
      </geometry>
      <material name="">
        <color rgba="0.792156862745098 0.819607843137255 0.933333333333333 1"/>
      </material>
    </visual>
    <collision>
      <origin rpy="0 0 0" xyz="0 0 0"/>
      <geometry>
        <mesh filename="package://tm5_900/meshes/lefthand_link.STL"/>
      </geometry>
    </collision>
  </link>
  <joint name="lefthand_joint" type="prismatic">
    <origin rpy="1.5708 0 1.5708" xyz="-0.01621 0.01429 0.0839"/>
    <parent link="gripper_base_link"/>
    <child link="lefthand_link"/>
    <axis xyz="0 0 1"/>
    <limit effort="130" lower="-0.015" upper="0.025" velocity="0.15"/>
    <dynamics damping="0.1" friction="0.1"/>
  </joint>
  <ros2_control name="tm5_900_ros2_control" type="system">
    <hardware>
      <!-- <plugin>mock_components/GenericSystem</plugin> -->
      <plugin>webots_ros2_control::Ros2ControlSystem</plugin>
      <!-- <plugin>gazebo_ros2_control/GazeboSystem</plugin> -->
    </hardware>
    <joint name="link1_joint">
      <command_interface name="position">
        <param name="min">-4.712</param>
        <param name="max">4.712</param>
      </command_interface>
      <state_interface name="position"/>
      <state_interface name="velocity"/>
      <state_interface name="effort"/>
    </joint>
    <joint name="link2_joint">
      <command_interface name="position">
        <param name="min">-3.141</param>
        <param name="max">3.141</param>
      </command_interface>
      <state_interface name="position"/>
      <state_interface name="velocity"/>
      <state_interface name="effort"/>
    </joint>
    <joint name="link3_joint">
      <command_interface name="position">
        <param name="min">-2.705</param>
        <param name="max">2.705</param>
      </command_interface>
      <state_interface name="position"/>
      <state_interface name="velocity"/>
      <state_interface name="effort"/>
    </joint>
    <joint name="link4_joint">
      <command_interface name="position">
        <param name="min">-3.141</param>
        <param name="max">3.141</param>
      </command_interface>
      <state_interface name="position"/>
      <state_interface name="velocity"/>
      <state_interface name="effort"/>
    </joint>
    <joint name="link5_joint">
      <command_interface name="position">
        <param name="min">-3.141</param>
        <param name="max">3.141</param>
      </command_interface>
      <state_interface name="position"/>
      <state_interface name="velocity"/>
      <state_interface name="effort"/>
    </joint>
    <joint name="link6_joint">
      <command_interface name="position">
        <param name="min">-4.712</param>
        <param name="max">4.712</param>
      </command_interface>
      <state_interface name="position"/>
      <state_interface name="velocity"/>
      <state_interface name="effort"/>
    </joint>
    <joint name="lefthand_joint">
      <command_interface name="position">
        <param name="min">-0.015</param>
        <param name="max">0.025</param>
      </command_interface>
      <state_interface name="position"/>
      <state_interface name="velocity"/>
      <state_interface name="effort"/>
    </joint>
    <joint name="righthand_joint">
      <command_interface name="position">
        <param name="min">-0.015</param>
        <param name="max">0.025</param>
      </command_interface>
      <state_interface name="position"/>
      <state_interface name="velocity"/>
      <state_interface name="effort"/>
    </joint>
  </ros2_control>
</robot>
