<?xml version="1.0" encoding="utf-8"?>
<!-- This URDF was automatically created by SolidWorks to URDF Exporter! Originally created by Stephen Brawner (brawner@gmail.com) 
     Commit Version: 1.6.0-4-g7f85cfe  Build Version: 1.6.7995.38578
     For more information, please see http://wiki.ros.org/sw_urdf_exporter -->
<robot
  name="tm5_900">
  <link
    name="base_link">
    <inertial>
      <origin
        xyz="1.4849575171727E-06 0.000238812327108207 0.0284834557903504"
        rpy="0 0 0" />
      <mass
        value="1.06337100987987" />
      <inertia
        ixx="0.00182018269042806"
        ixy="1.62969451944762E-06"
        ixz="-5.39273362848716E-08"
        iyy="0.00185111927565704"
        iyz="-5.6175556337264E-06"
        izz="0.00290659564069462" />
    </inertial>
    <visual>
      <origin
        xyz="0 0 0"
        rpy="0 0 0" />
      <geometry>
        <mesh
          filename="package://tm5_900/meshes/base_link.STL" />
      </geometry>
      <material
        name="">
        <colors
          rgba="0.792156862745098 0.819607843137255 0.933333333333333 1" />
      </material>
    </visual>
    <collision>
      <origin
        xyz="0 0 0"
        rpy="0 0 0" />
      <geometry>
        <mesh
          filename="package://tm5_900/meshes/base_link.STL" />
      </geometry>
    </collision>
  </link>
  <link
    name="link1">
    <inertial>
      <origin
        xyz="-0.00498552832696797 -0.00134957802409452 0.0798207058794638"
        rpy="0 0 0" />
      <mass
        value="1.94965621478227" />
      <inertia
        ixx="0.0033604880068714"
        ixy="-1.70483404424875E-05"
        ixz="0.000473241173342463"
        iyy="0.00341893252114965"
        iyz="0.000128103470837121"
        izz="0.0037480043435368" />
    </inertial>
    <visual>
      <origin
        xyz="0 0 0"
        rpy="0 0 0" />
      <geometry>
        <mesh
          filename="package://tm5_900/meshes/link1.STL" />
      </geometry>
      <material
        name="">
        <color
          rgba="0.792156862745098 0.819607843137255 0.933333333333333 1" />
      </material>
    </visual>
    <collision>
      <origin
        xyz="0 0 0"
        rpy="0 0 0" />
      <geometry>
        <mesh
          filename="package://tm5_900/meshes/link1.STL" />
      </geometry>
    </collision>
  </link>
  <joint
    name="link1_joint"
    type="revolute">
    <origin
      xyz="0 0 0.066"
      rpy="0 0 0" />
    <parent
      link="base_link" />
    <child
      link="link1" />
    <axis
      xyz="0 0 -1" />
    <limit
      lower="-4.712"
      upper="4.712"
      effort="150"
      velocity="3.141" />
    <dynamics
      damping="0.1"
      friction="0.1" />
  </joint>
  <link
    name="link2">
    <inertial>
      <origin
        xyz="-0.0214730943136532 0.213422470997644 0.0804767368390672"
        rpy="0 0 0" />
      <mass
        value="6.39944621023157" />
      <inertia
        ixx="0.0299352857425063"
        ixy="0.00199317563709057"
        ixz="-6.09971564403955E-09"
        iyy="0.0103253522039345"
        iyz="6.56772161661138E-09"
        izz="0.030784769235649" />
    </inertial>
    <visual>
      <origin
        xyz="0 0 0"
        rpy="0 0 0" />
      <geometry>
        <mesh
          filename="package://tm5_900/meshes/link2.STL" />
      </geometry>
      <material
        name="">
        <color
          rgba="0.792156862745098 0.819607843137255 0.933333333333333 1" />
      </material>
    </visual>
    <collision>
      <origin
        xyz="0 0 0"
        rpy="0 0 0" />
      <geometry>
        <mesh
          filename="package://tm5_900/meshes/link2.STL" />
      </geometry>
    </collision>
  </link>
  <joint
    name="link2_joint"
    type="revolute">
    <origin
      xyz="-0.064479 -0.017456 0.0815"
      rpy="1.5708 0 -1.3064" />
    <parent
      link="link1" />
    <child
      link="link2" />
    <axis
      xyz="0 0 -1" />
    <limit
      lower="-3.141"
      upper="3.141"
      effort="150"
      velocity="3.141" />
    <dynamics
      damping="0.1"
      friction="0.1" />
  </joint>
  <link
    name="link3">
    <inertial>
      <origin
        xyz="0.13185181232973 0.166464143195079 0.0470686716905526"
        rpy="0 0 0" />
      <mass
        value="2.93877134811613" />
      <inertia
        ixx="0.0097806981469156"
        ixy="-0.0055806899749397"
        ixz="-3.16089596284092E-05"
        iyy="0.00715513619347662"
        iyz="-4.00676705957807E-05"
        izz="0.014350517191736" />
    </inertial>
    <visual>
      <origin
        xyz="0 0 0"
        rpy="0 0 0" />
      <geometry>
        <mesh
          filename="package://tm5_900/meshes/link3.STL" />
      </geometry>
      <material
        name="">
        <color
          rgba="0.792156862745098 0.819607843137255 0.933333333333333 1" />
      </material>
    </visual>
    <collision>
      <origin
        xyz="0 0 0"
        rpy="0 0 0" />
      <geometry>
        <mesh
          filename="package://tm5_900/meshes/link3.STL" />
      </geometry>
    </collision>
  </link>
  <joint
    name="link3_joint"
    type="revolute">
    <origin
      xyz="-0.042946 0.42684 0"
      rpy="3.1416 0 -3.0413" />
    <parent
      link="link2" />
    <child
      link="link3" />
    <axis
      xyz="0 0 -1" />
    <limit
      lower="-2.705"
      upper="2.705"
      effort="150"
      velocity="3.141" />
    <dynamics
      damping="0.1"
      friction="0.1" />
  </joint>
  <link
    name="link4">
    <inertial>
      <origin
        xyz="0.000958659017332719 0.00400207698260102 0.0584361357448289"
        rpy="0 0 0" />
      <mass
        value="0.784300640139411" />
      <inertia
        ixx="0.000777536473590337"
        ixy="-2.83897001187057E-06"
        ixz="-2.62218325637417E-05"
        iyy="0.000765864136417388"
        iyz="-0.000109647383909337"
        izz="0.000826338586221481" />
    </inertial>
    <visual>
      <origin
        xyz="0 0 0"
        rpy="0 0 0" />
      <geometry>
        <mesh
          filename="package://tm5_900/meshes/link4.STL" />
      </geometry>
      <material
        name="">
        <color
          rgba="0.792156862745098 0.819607843137255 0.933333333333333 1" />
      </material>
    </visual>
    <collision>
      <origin
        xyz="0 0 0"
        rpy="0 0 0" />
      <geometry>
        <mesh
          filename="package://tm5_900/meshes/link4.STL" />
      </geometry>
    </collision>
  </link>
  <joint
    name="link4_joint"
    type="revolute">
    <origin
      xyz="0.2555 0.32257 -0.008"
      rpy="-3.1416 0 2.4717" />
    <parent
      link="link3" />
    <child
      link="link4" />
    <axis
      xyz="0 0 -1" />
    <limit
      lower="-3.141"
      upper="3.141"
      effort="150"
      velocity="3.927" />
    <dynamics
      damping="0.1"
      friction="0.1" />
  </joint>
  <link
    name="link5">
    <inertial>
      <origin
        xyz="6.37683558368796E-05 -5.28389041531963E-06 0.0455846354589133"
        rpy="0 0 0" />
      <mass
        value="0.784295948614627" />
      <inertia
        ixx="0.000825367051038267"
        ixy="-6.78872332810984E-06"
        ixz="-0.000111586164347964"
        iyy="0.000779162700145123"
        iyz="1.60843062587631E-05"
        izz="0.0007652069463931" />
    </inertial>
    <visual>
      <origin
        xyz="0 0 0"
        rpy="0 0 0" />
      <geometry>
        <mesh
          filename="package://tm5_900/meshes/link5.STL" />
      </geometry>
      <material
        name="">
        <color
          rgba="0.792156862745098 0.819607843137255 0.933333333333333 1" />
      </material>
    </visual>
    <collision>
      <origin
        xyz="0 0 0"
        rpy="0 0 0" />
      <geometry>
        <mesh
          filename="package://tm5_900/meshes/link5.STL" />
      </geometry>
    </collision>
  </link>
  <joint
    name="link5_joint"
    type="revolute">
    <origin
      xyz="0.011533 0.048343 0.0585"
      rpy="-0.53433 -1.5708 -1.2417" />
    <parent
      link="link4" />
    <child
      link="link5" />
    <axis
      xyz="0 0 -1" />
    <limit
      lower="-3.141"
      upper="3.141"
      effort="150"
      velocity="3.927" />
    <dynamics
      damping="0.1"
      friction="0.1" />
  </joint>
  <link
    name="link6">
    <inertial>
      <origin
        xyz="-0.00322518472339128 0.0419255525875091 0.0404958504356016"
        rpy="0 0 0" />
      <mass
        value="0.667417377007754" />
      <inertia
        ixx="0.000832763395505331"
        ixy="3.66637045819054E-05"
        ixz="1.82606944657742E-06"
        iyy="0.000383001674039478"
        iyz="-1.42873956185042E-05"
        izz="0.0009523250352178" />
    </inertial>
    <visual>
      <origin
        xyz="0 0 0"
        rpy="0 0 0" />
      <geometry>
        <mesh
          filename="package://tm5_900/meshes/link6.STL" />
      </geometry>
      <material
        name="">
        <color
          rgba="0.792156862745098 0.819607843137255 0.933333333333333 1" />
      </material>
    </visual>
    <collision>
      <origin
        xyz="0 0 0"
        rpy="0 0 0" />
      <geometry>
        <mesh
          filename="package://tm5_900/meshes/link6.STL" />
      </geometry>
    </collision>
  </link>
  <joint
    name="link6_joint"
    type="revolute">
    <origin
      xyz="0.057893 -0.0084026 0.0497"
      rpy="1.5708 0 1.4267" />
    <parent
      link="link5" />
    <child
      link="link6" />
    <axis
      xyz="0 0 -1" />
    <limit
      lower="-4.712"
      upper="4.712"
      effort="150"
      velocity="3.927" />
    <dynamics
      damping="0.1"
      friction="0.1" />
  </joint>
</robot>